{
 "cells": [
  {
   "cell_type": "code",
   "execution_count": 1,
   "metadata": {},
   "outputs": [],
   "source": [
    "from src.environment._ENV_capture import Board\n",
    "from src.agent._AGENT_capture import Agent\n",
    "from src.learn._q_learning_capture import Q_learning"
   ]
  },
  {
   "cell_type": "markdown",
   "metadata": {},
   "source": [
    "# Capture chess\n",
    "### Q-learning"
   ]
  },
  {
   "cell_type": "code",
   "execution_count": 2,
   "metadata": {},
   "outputs": [],
   "source": [
    "board = Board()\n",
    "agent = Agent(network='conv',gamma=0.1,lr=0.07)\n",
    "R = Q_learning(agent,board)"
   ]
  },
  {
   "cell_type": "code",
   "execution_count": 3,
   "metadata": {},
   "outputs": [
    {
     "name": "stdout",
     "output_type": "stream",
     "text": [
      "iter 0\n"
     ]
    },
    {
     "ename": "UnimplementedError",
     "evalue": "Graph execution error:\n\nDetected at node 'model/conv2d/Conv2D' defined at (most recent call last):\n    File \"/Users/valeriainsogna/anaconda3/envs/RL/lib/python3.9/runpy.py\", line 197, in _run_module_as_main\n      return _run_code(code, main_globals, None,\n    File \"/Users/valeriainsogna/anaconda3/envs/RL/lib/python3.9/runpy.py\", line 87, in _run_code\n      exec(code, run_globals)\n    File \"/Users/valeriainsogna/anaconda3/envs/RL/lib/python3.9/site-packages/ipykernel_launcher.py\", line 17, in <module>\n      app.launch_new_instance()\n    File \"/Users/valeriainsogna/anaconda3/envs/RL/lib/python3.9/site-packages/traitlets/config/application.py\", line 1043, in launch_instance\n      app.start()\n    File \"/Users/valeriainsogna/anaconda3/envs/RL/lib/python3.9/site-packages/ipykernel/kernelapp.py\", line 728, in start\n      self.io_loop.start()\n    File \"/Users/valeriainsogna/anaconda3/envs/RL/lib/python3.9/site-packages/tornado/platform/asyncio.py\", line 195, in start\n      self.asyncio_loop.run_forever()\n    File \"/Users/valeriainsogna/anaconda3/envs/RL/lib/python3.9/asyncio/base_events.py\", line 601, in run_forever\n      self._run_once()\n    File \"/Users/valeriainsogna/anaconda3/envs/RL/lib/python3.9/asyncio/base_events.py\", line 1905, in _run_once\n      handle._run()\n    File \"/Users/valeriainsogna/anaconda3/envs/RL/lib/python3.9/asyncio/events.py\", line 80, in _run\n      self._context.run(self._callback, *self._args)\n    File \"/Users/valeriainsogna/anaconda3/envs/RL/lib/python3.9/site-packages/ipykernel/kernelbase.py\", line 516, in dispatch_queue\n      await self.process_one()\n    File \"/Users/valeriainsogna/anaconda3/envs/RL/lib/python3.9/site-packages/ipykernel/kernelbase.py\", line 505, in process_one\n      await dispatch(*args)\n    File \"/Users/valeriainsogna/anaconda3/envs/RL/lib/python3.9/site-packages/ipykernel/kernelbase.py\", line 412, in dispatch_shell\n      await result\n    File \"/Users/valeriainsogna/anaconda3/envs/RL/lib/python3.9/site-packages/ipykernel/kernelbase.py\", line 740, in execute_request\n      reply_content = await reply_content\n    File \"/Users/valeriainsogna/anaconda3/envs/RL/lib/python3.9/site-packages/ipykernel/ipkernel.py\", line 422, in do_execute\n      res = shell.run_cell(\n    File \"/Users/valeriainsogna/anaconda3/envs/RL/lib/python3.9/site-packages/ipykernel/zmqshell.py\", line 540, in run_cell\n      return super().run_cell(*args, **kwargs)\n    File \"/Users/valeriainsogna/anaconda3/envs/RL/lib/python3.9/site-packages/IPython/core/interactiveshell.py\", line 3009, in run_cell\n      result = self._run_cell(\n    File \"/Users/valeriainsogna/anaconda3/envs/RL/lib/python3.9/site-packages/IPython/core/interactiveshell.py\", line 3064, in _run_cell\n      result = runner(coro)\n    File \"/Users/valeriainsogna/anaconda3/envs/RL/lib/python3.9/site-packages/IPython/core/async_helpers.py\", line 129, in _pseudo_sync_runner\n      coro.send(None)\n    File \"/Users/valeriainsogna/anaconda3/envs/RL/lib/python3.9/site-packages/IPython/core/interactiveshell.py\", line 3269, in run_cell_async\n      has_raised = await self.run_ast_nodes(code_ast.body, cell_name,\n    File \"/Users/valeriainsogna/anaconda3/envs/RL/lib/python3.9/site-packages/IPython/core/interactiveshell.py\", line 3448, in run_ast_nodes\n      if await self.run_code(code, result, async_=asy):\n    File \"/Users/valeriainsogna/anaconda3/envs/RL/lib/python3.9/site-packages/IPython/core/interactiveshell.py\", line 3508, in run_code\n      exec(code_obj, self.user_global_ns, self.user_ns)\n    File \"/var/folders/ql/622b8f7n6lv04w96qrs3vdgh0000gn/T/ipykernel_40366/700820216.py\", line 1, in <module>\n      game = R.learn(100)\n    File \"/Users/valeriainsogna/Desktop/ReinForceMate/src/learn/_q_learning_capture.py\", line 43, in learn\n      self.play_game(k, greedy=greedy)\n    File \"/Users/valeriainsogna/Desktop/ReinForceMate/src/learn/_q_learning_capture.py\", line 111, in play_game\n      self.update_agent(turncount)\n    File \"/Users/valeriainsogna/Desktop/ReinForceMate/src/learn/_q_learning_capture.py\", line 148, in update_agent\n      td_errors = self.agent.network_update(minibatch)\n    File \"/Users/valeriainsogna/Desktop/ReinForceMate/src/agent/_AGENT_capture.py\", line 91, in network_update\n      self.fixed_model.predict(np.stack(new_states, axis=0)), axis=1)\n    File \"/Users/valeriainsogna/anaconda3/envs/RL/lib/python3.9/site-packages/keras/src/utils/traceback_utils.py\", line 65, in error_handler\n      return fn(*args, **kwargs)\n    File \"/Users/valeriainsogna/anaconda3/envs/RL/lib/python3.9/site-packages/keras/src/engine/training.py\", line 2554, in predict\n      tmp_batch_outputs = self.predict_function(iterator)\n    File \"/Users/valeriainsogna/anaconda3/envs/RL/lib/python3.9/site-packages/keras/src/engine/training.py\", line 2341, in predict_function\n      return step_function(self, iterator)\n    File \"/Users/valeriainsogna/anaconda3/envs/RL/lib/python3.9/site-packages/keras/src/engine/training.py\", line 2327, in step_function\n      outputs = model.distribute_strategy.run(run_step, args=(data,))\n    File \"/Users/valeriainsogna/anaconda3/envs/RL/lib/python3.9/site-packages/keras/src/engine/training.py\", line 2315, in run_step\n      outputs = model.predict_step(data)\n    File \"/Users/valeriainsogna/anaconda3/envs/RL/lib/python3.9/site-packages/keras/src/engine/training.py\", line 2283, in predict_step\n      return self(x, training=False)\n    File \"/Users/valeriainsogna/anaconda3/envs/RL/lib/python3.9/site-packages/keras/src/utils/traceback_utils.py\", line 65, in error_handler\n      return fn(*args, **kwargs)\n    File \"/Users/valeriainsogna/anaconda3/envs/RL/lib/python3.9/site-packages/keras/src/engine/training.py\", line 569, in __call__\n      return super().__call__(*args, **kwargs)\n    File \"/Users/valeriainsogna/anaconda3/envs/RL/lib/python3.9/site-packages/keras/src/utils/traceback_utils.py\", line 65, in error_handler\n      return fn(*args, **kwargs)\n    File \"/Users/valeriainsogna/anaconda3/envs/RL/lib/python3.9/site-packages/keras/src/engine/base_layer.py\", line 1150, in __call__\n      outputs = call_fn(inputs, *args, **kwargs)\n    File \"/Users/valeriainsogna/anaconda3/envs/RL/lib/python3.9/site-packages/keras/src/utils/traceback_utils.py\", line 96, in error_handler\n      return fn(*args, **kwargs)\n    File \"/Users/valeriainsogna/anaconda3/envs/RL/lib/python3.9/site-packages/keras/src/engine/functional.py\", line 512, in call\n      return self._run_internal_graph(inputs, training=training, mask=mask)\n    File \"/Users/valeriainsogna/anaconda3/envs/RL/lib/python3.9/site-packages/keras/src/engine/functional.py\", line 669, in _run_internal_graph\n      outputs = node.layer(*args, **kwargs)\n    File \"/Users/valeriainsogna/anaconda3/envs/RL/lib/python3.9/site-packages/keras/src/utils/traceback_utils.py\", line 65, in error_handler\n      return fn(*args, **kwargs)\n    File \"/Users/valeriainsogna/anaconda3/envs/RL/lib/python3.9/site-packages/keras/src/engine/base_layer.py\", line 1150, in __call__\n      outputs = call_fn(inputs, *args, **kwargs)\n    File \"/Users/valeriainsogna/anaconda3/envs/RL/lib/python3.9/site-packages/keras/src/utils/traceback_utils.py\", line 96, in error_handler\n      return fn(*args, **kwargs)\n    File \"/Users/valeriainsogna/anaconda3/envs/RL/lib/python3.9/site-packages/keras/src/layers/convolutional/base_conv.py\", line 290, in call\n      outputs = self.convolution_op(inputs, self.kernel)\n    File \"/Users/valeriainsogna/anaconda3/envs/RL/lib/python3.9/site-packages/keras/src/layers/convolutional/base_conv.py\", line 262, in convolution_op\n      return tf.nn.convolution(\nNode: 'model/conv2d/Conv2D'\nThe Conv2D op currently only supports the NHWC tensor format on the CPU. The op was given the format: NCHW\n\t [[{{node model/conv2d/Conv2D}}]] [Op:__inference_predict_function_353]",
     "output_type": "error",
     "traceback": [
      "\u001b[0;31m---------------------------------------------------------------------------\u001b[0m",
      "\u001b[0;31mUnimplementedError\u001b[0m                        Traceback (most recent call last)",
      "Cell \u001b[0;32mIn[3], line 1\u001b[0m\n\u001b[0;32m----> 1\u001b[0m game \u001b[39m=\u001b[39m R\u001b[39m.\u001b[39;49mlearn(\u001b[39m100\u001b[39;49m)\n",
      "File \u001b[0;32m~/Desktop/ReinForceMate/src/learn/_q_learning_capture.py:43\u001b[0m, in \u001b[0;36mQ_learning.learn\u001b[0;34m(self, iters, c)\u001b[0m\n\u001b[1;32m     41\u001b[0m     greedy \u001b[39m=\u001b[39m \u001b[39mTrue\u001b[39;00m \u001b[39mif\u001b[39;00m k \u001b[39m==\u001b[39m iters \u001b[39m-\u001b[39m \u001b[39m1\u001b[39m \u001b[39melse\u001b[39;00m \u001b[39mFalse\u001b[39;00m\n\u001b[1;32m     42\u001b[0m     \u001b[39mself\u001b[39m\u001b[39m.\u001b[39menv\u001b[39m.\u001b[39mreset()\n\u001b[0;32m---> 43\u001b[0m     \u001b[39mself\u001b[39;49m\u001b[39m.\u001b[39;49mplay_game(k, greedy\u001b[39m=\u001b[39;49mgreedy)\n\u001b[1;32m     45\u001b[0m pgn \u001b[39m=\u001b[39m Game\u001b[39m.\u001b[39mfrom_board(\u001b[39mself\u001b[39m\u001b[39m.\u001b[39menv\u001b[39m.\u001b[39mboard)\n\u001b[1;32m     46\u001b[0m reward_smooth \u001b[39m=\u001b[39m pd\u001b[39m.\u001b[39mDataFrame(\u001b[39mself\u001b[39m\u001b[39m.\u001b[39mreward_trace)\n",
      "File \u001b[0;32m~/Desktop/ReinForceMate/src/learn/_q_learning_capture.py:111\u001b[0m, in \u001b[0;36mQ_learning.play_game\u001b[0;34m(self, k, greedy, maxiter)\u001b[0m\n\u001b[1;32m    107\u001b[0m     \u001b[39mself\u001b[39m\u001b[39m.\u001b[39msampling_probs\u001b[39m.\u001b[39mappend(\u001b[39m1\u001b[39m)\n\u001b[1;32m    109\u001b[0m     \u001b[39mself\u001b[39m\u001b[39m.\u001b[39mreward_trace\u001b[39m.\u001b[39mappend(reward)\n\u001b[0;32m--> 111\u001b[0m     \u001b[39mself\u001b[39;49m\u001b[39m.\u001b[39;49mupdate_agent(turncount)\n\u001b[1;32m    113\u001b[0m \u001b[39mreturn\u001b[39;00m \u001b[39mself\u001b[39m\u001b[39m.\u001b[39menv\u001b[39m.\u001b[39mboard\n",
      "File \u001b[0;32m~/Desktop/ReinForceMate/src/learn/_q_learning_capture.py:148\u001b[0m, in \u001b[0;36mQ_learning.update_agent\u001b[0;34m(self, turncount)\u001b[0m\n\u001b[1;32m    146\u001b[0m \u001b[39mif\u001b[39;00m turncount \u001b[39m<\u001b[39m \u001b[39mlen\u001b[39m(\u001b[39mself\u001b[39m\u001b[39m.\u001b[39mmemory):\n\u001b[1;32m    147\u001b[0m     minibatch, indices \u001b[39m=\u001b[39m \u001b[39mself\u001b[39m\u001b[39m.\u001b[39msample_memory(turncount)\n\u001b[0;32m--> 148\u001b[0m     td_errors \u001b[39m=\u001b[39m \u001b[39mself\u001b[39;49m\u001b[39m.\u001b[39;49magent\u001b[39m.\u001b[39;49mnetwork_update(minibatch)\n\u001b[1;32m    149\u001b[0m     \u001b[39mfor\u001b[39;00m n, i \u001b[39min\u001b[39;00m \u001b[39menumerate\u001b[39m(indices):\n\u001b[1;32m    150\u001b[0m         \u001b[39mself\u001b[39m\u001b[39m.\u001b[39msampling_probs[i] \u001b[39m=\u001b[39m np\u001b[39m.\u001b[39mabs(td_errors[n])\n",
      "File \u001b[0;32m~/Desktop/ReinForceMate/src/agent/_AGENT_capture.py:91\u001b[0m, in \u001b[0;36mAgent.network_update\u001b[0;34m(self, minibatch)\u001b[0m\n\u001b[1;32m     88\u001b[0m     \u001b[39melse\u001b[39;00m:\n\u001b[1;32m     89\u001b[0m         episode_ends\u001b[39m.\u001b[39mappend(\u001b[39m1\u001b[39m)\n\u001b[1;32m     90\u001b[0m q_target \u001b[39m=\u001b[39m np\u001b[39m.\u001b[39marray(rewards) \u001b[39m+\u001b[39m np\u001b[39m.\u001b[39marray(episode_ends) \u001b[39m*\u001b[39m \u001b[39mself\u001b[39m\u001b[39m.\u001b[39mgamma \u001b[39m*\u001b[39m np\u001b[39m.\u001b[39mmax(\n\u001b[0;32m---> 91\u001b[0m     \u001b[39mself\u001b[39;49m\u001b[39m.\u001b[39;49mfixed_model\u001b[39m.\u001b[39;49mpredict(np\u001b[39m.\u001b[39;49mstack(new_states, axis\u001b[39m=\u001b[39;49m\u001b[39m0\u001b[39;49m)), axis\u001b[39m=\u001b[39m\u001b[39m1\u001b[39m)\n\u001b[1;32m     92\u001b[0m q_state \u001b[39m=\u001b[39m \u001b[39mself\u001b[39m\u001b[39m.\u001b[39mmodel\u001b[39m.\u001b[39mpredict(np\u001b[39m.\u001b[39mstack(states, axis\u001b[39m=\u001b[39m\u001b[39m0\u001b[39m))\n\u001b[1;32m     93\u001b[0m q_state \u001b[39m=\u001b[39m np\u001b[39m.\u001b[39mreshape(q_state, (\u001b[39mlen\u001b[39m(minibatch), \u001b[39m64\u001b[39m, \u001b[39m64\u001b[39m))\n",
      "File \u001b[0;32m~/anaconda3/envs/RL/lib/python3.9/site-packages/keras/src/utils/traceback_utils.py:70\u001b[0m, in \u001b[0;36mfilter_traceback.<locals>.error_handler\u001b[0;34m(*args, **kwargs)\u001b[0m\n\u001b[1;32m     67\u001b[0m     filtered_tb \u001b[39m=\u001b[39m _process_traceback_frames(e\u001b[39m.\u001b[39m__traceback__)\n\u001b[1;32m     68\u001b[0m     \u001b[39m# To get the full stack trace, call:\u001b[39;00m\n\u001b[1;32m     69\u001b[0m     \u001b[39m# `tf.debugging.disable_traceback_filtering()`\u001b[39;00m\n\u001b[0;32m---> 70\u001b[0m     \u001b[39mraise\u001b[39;00m e\u001b[39m.\u001b[39mwith_traceback(filtered_tb) \u001b[39mfrom\u001b[39;00m \u001b[39mNone\u001b[39;00m\n\u001b[1;32m     71\u001b[0m \u001b[39mfinally\u001b[39;00m:\n\u001b[1;32m     72\u001b[0m     \u001b[39mdel\u001b[39;00m filtered_tb\n",
      "File \u001b[0;32m~/anaconda3/envs/RL/lib/python3.9/site-packages/tensorflow/python/eager/execute.py:53\u001b[0m, in \u001b[0;36mquick_execute\u001b[0;34m(op_name, num_outputs, inputs, attrs, ctx, name)\u001b[0m\n\u001b[1;32m     51\u001b[0m \u001b[39mtry\u001b[39;00m:\n\u001b[1;32m     52\u001b[0m   ctx\u001b[39m.\u001b[39mensure_initialized()\n\u001b[0;32m---> 53\u001b[0m   tensors \u001b[39m=\u001b[39m pywrap_tfe\u001b[39m.\u001b[39mTFE_Py_Execute(ctx\u001b[39m.\u001b[39m_handle, device_name, op_name,\n\u001b[1;32m     54\u001b[0m                                       inputs, attrs, num_outputs)\n\u001b[1;32m     55\u001b[0m \u001b[39mexcept\u001b[39;00m core\u001b[39m.\u001b[39m_NotOkStatusException \u001b[39mas\u001b[39;00m e:\n\u001b[1;32m     56\u001b[0m   \u001b[39mif\u001b[39;00m name \u001b[39mis\u001b[39;00m \u001b[39mnot\u001b[39;00m \u001b[39mNone\u001b[39;00m:\n",
      "\u001b[0;31mUnimplementedError\u001b[0m: Graph execution error:\n\nDetected at node 'model/conv2d/Conv2D' defined at (most recent call last):\n    File \"/Users/valeriainsogna/anaconda3/envs/RL/lib/python3.9/runpy.py\", line 197, in _run_module_as_main\n      return _run_code(code, main_globals, None,\n    File \"/Users/valeriainsogna/anaconda3/envs/RL/lib/python3.9/runpy.py\", line 87, in _run_code\n      exec(code, run_globals)\n    File \"/Users/valeriainsogna/anaconda3/envs/RL/lib/python3.9/site-packages/ipykernel_launcher.py\", line 17, in <module>\n      app.launch_new_instance()\n    File \"/Users/valeriainsogna/anaconda3/envs/RL/lib/python3.9/site-packages/traitlets/config/application.py\", line 1043, in launch_instance\n      app.start()\n    File \"/Users/valeriainsogna/anaconda3/envs/RL/lib/python3.9/site-packages/ipykernel/kernelapp.py\", line 728, in start\n      self.io_loop.start()\n    File \"/Users/valeriainsogna/anaconda3/envs/RL/lib/python3.9/site-packages/tornado/platform/asyncio.py\", line 195, in start\n      self.asyncio_loop.run_forever()\n    File \"/Users/valeriainsogna/anaconda3/envs/RL/lib/python3.9/asyncio/base_events.py\", line 601, in run_forever\n      self._run_once()\n    File \"/Users/valeriainsogna/anaconda3/envs/RL/lib/python3.9/asyncio/base_events.py\", line 1905, in _run_once\n      handle._run()\n    File \"/Users/valeriainsogna/anaconda3/envs/RL/lib/python3.9/asyncio/events.py\", line 80, in _run\n      self._context.run(self._callback, *self._args)\n    File \"/Users/valeriainsogna/anaconda3/envs/RL/lib/python3.9/site-packages/ipykernel/kernelbase.py\", line 516, in dispatch_queue\n      await self.process_one()\n    File \"/Users/valeriainsogna/anaconda3/envs/RL/lib/python3.9/site-packages/ipykernel/kernelbase.py\", line 505, in process_one\n      await dispatch(*args)\n    File \"/Users/valeriainsogna/anaconda3/envs/RL/lib/python3.9/site-packages/ipykernel/kernelbase.py\", line 412, in dispatch_shell\n      await result\n    File \"/Users/valeriainsogna/anaconda3/envs/RL/lib/python3.9/site-packages/ipykernel/kernelbase.py\", line 740, in execute_request\n      reply_content = await reply_content\n    File \"/Users/valeriainsogna/anaconda3/envs/RL/lib/python3.9/site-packages/ipykernel/ipkernel.py\", line 422, in do_execute\n      res = shell.run_cell(\n    File \"/Users/valeriainsogna/anaconda3/envs/RL/lib/python3.9/site-packages/ipykernel/zmqshell.py\", line 540, in run_cell\n      return super().run_cell(*args, **kwargs)\n    File \"/Users/valeriainsogna/anaconda3/envs/RL/lib/python3.9/site-packages/IPython/core/interactiveshell.py\", line 3009, in run_cell\n      result = self._run_cell(\n    File \"/Users/valeriainsogna/anaconda3/envs/RL/lib/python3.9/site-packages/IPython/core/interactiveshell.py\", line 3064, in _run_cell\n      result = runner(coro)\n    File \"/Users/valeriainsogna/anaconda3/envs/RL/lib/python3.9/site-packages/IPython/core/async_helpers.py\", line 129, in _pseudo_sync_runner\n      coro.send(None)\n    File \"/Users/valeriainsogna/anaconda3/envs/RL/lib/python3.9/site-packages/IPython/core/interactiveshell.py\", line 3269, in run_cell_async\n      has_raised = await self.run_ast_nodes(code_ast.body, cell_name,\n    File \"/Users/valeriainsogna/anaconda3/envs/RL/lib/python3.9/site-packages/IPython/core/interactiveshell.py\", line 3448, in run_ast_nodes\n      if await self.run_code(code, result, async_=asy):\n    File \"/Users/valeriainsogna/anaconda3/envs/RL/lib/python3.9/site-packages/IPython/core/interactiveshell.py\", line 3508, in run_code\n      exec(code_obj, self.user_global_ns, self.user_ns)\n    File \"/var/folders/ql/622b8f7n6lv04w96qrs3vdgh0000gn/T/ipykernel_40366/700820216.py\", line 1, in <module>\n      game = R.learn(100)\n    File \"/Users/valeriainsogna/Desktop/ReinForceMate/src/learn/_q_learning_capture.py\", line 43, in learn\n      self.play_game(k, greedy=greedy)\n    File \"/Users/valeriainsogna/Desktop/ReinForceMate/src/learn/_q_learning_capture.py\", line 111, in play_game\n      self.update_agent(turncount)\n    File \"/Users/valeriainsogna/Desktop/ReinForceMate/src/learn/_q_learning_capture.py\", line 148, in update_agent\n      td_errors = self.agent.network_update(minibatch)\n    File \"/Users/valeriainsogna/Desktop/ReinForceMate/src/agent/_AGENT_capture.py\", line 91, in network_update\n      self.fixed_model.predict(np.stack(new_states, axis=0)), axis=1)\n    File \"/Users/valeriainsogna/anaconda3/envs/RL/lib/python3.9/site-packages/keras/src/utils/traceback_utils.py\", line 65, in error_handler\n      return fn(*args, **kwargs)\n    File \"/Users/valeriainsogna/anaconda3/envs/RL/lib/python3.9/site-packages/keras/src/engine/training.py\", line 2554, in predict\n      tmp_batch_outputs = self.predict_function(iterator)\n    File \"/Users/valeriainsogna/anaconda3/envs/RL/lib/python3.9/site-packages/keras/src/engine/training.py\", line 2341, in predict_function\n      return step_function(self, iterator)\n    File \"/Users/valeriainsogna/anaconda3/envs/RL/lib/python3.9/site-packages/keras/src/engine/training.py\", line 2327, in step_function\n      outputs = model.distribute_strategy.run(run_step, args=(data,))\n    File \"/Users/valeriainsogna/anaconda3/envs/RL/lib/python3.9/site-packages/keras/src/engine/training.py\", line 2315, in run_step\n      outputs = model.predict_step(data)\n    File \"/Users/valeriainsogna/anaconda3/envs/RL/lib/python3.9/site-packages/keras/src/engine/training.py\", line 2283, in predict_step\n      return self(x, training=False)\n    File \"/Users/valeriainsogna/anaconda3/envs/RL/lib/python3.9/site-packages/keras/src/utils/traceback_utils.py\", line 65, in error_handler\n      return fn(*args, **kwargs)\n    File \"/Users/valeriainsogna/anaconda3/envs/RL/lib/python3.9/site-packages/keras/src/engine/training.py\", line 569, in __call__\n      return super().__call__(*args, **kwargs)\n    File \"/Users/valeriainsogna/anaconda3/envs/RL/lib/python3.9/site-packages/keras/src/utils/traceback_utils.py\", line 65, in error_handler\n      return fn(*args, **kwargs)\n    File \"/Users/valeriainsogna/anaconda3/envs/RL/lib/python3.9/site-packages/keras/src/engine/base_layer.py\", line 1150, in __call__\n      outputs = call_fn(inputs, *args, **kwargs)\n    File \"/Users/valeriainsogna/anaconda3/envs/RL/lib/python3.9/site-packages/keras/src/utils/traceback_utils.py\", line 96, in error_handler\n      return fn(*args, **kwargs)\n    File \"/Users/valeriainsogna/anaconda3/envs/RL/lib/python3.9/site-packages/keras/src/engine/functional.py\", line 512, in call\n      return self._run_internal_graph(inputs, training=training, mask=mask)\n    File \"/Users/valeriainsogna/anaconda3/envs/RL/lib/python3.9/site-packages/keras/src/engine/functional.py\", line 669, in _run_internal_graph\n      outputs = node.layer(*args, **kwargs)\n    File \"/Users/valeriainsogna/anaconda3/envs/RL/lib/python3.9/site-packages/keras/src/utils/traceback_utils.py\", line 65, in error_handler\n      return fn(*args, **kwargs)\n    File \"/Users/valeriainsogna/anaconda3/envs/RL/lib/python3.9/site-packages/keras/src/engine/base_layer.py\", line 1150, in __call__\n      outputs = call_fn(inputs, *args, **kwargs)\n    File \"/Users/valeriainsogna/anaconda3/envs/RL/lib/python3.9/site-packages/keras/src/utils/traceback_utils.py\", line 96, in error_handler\n      return fn(*args, **kwargs)\n    File \"/Users/valeriainsogna/anaconda3/envs/RL/lib/python3.9/site-packages/keras/src/layers/convolutional/base_conv.py\", line 290, in call\n      outputs = self.convolution_op(inputs, self.kernel)\n    File \"/Users/valeriainsogna/anaconda3/envs/RL/lib/python3.9/site-packages/keras/src/layers/convolutional/base_conv.py\", line 262, in convolution_op\n      return tf.nn.convolution(\nNode: 'model/conv2d/Conv2D'\nThe Conv2D op currently only supports the NHWC tensor format on the CPU. The op was given the format: NCHW\n\t [[{{node model/conv2d/Conv2D}}]] [Op:__inference_predict_function_353]"
     ]
    }
   ],
   "source": [
    "game = R.learn(100)"
   ]
  }
 ],
 "metadata": {
  "kernelspec": {
   "display_name": "DL",
   "language": "python",
   "name": "python3"
  },
  "language_info": {
   "codemirror_mode": {
    "name": "ipython",
    "version": 3
   },
   "file_extension": ".py",
   "mimetype": "text/x-python",
   "name": "python",
   "nbconvert_exporter": "python",
   "pygments_lexer": "ipython3",
   "version": "3.9.16"
  },
  "orig_nbformat": 4
 },
 "nbformat": 4,
 "nbformat_minor": 2
}
